Workbook

Sheet Summary
A1: By epic
A2: Epic ID | B2: Epic | C2: Stories | D2: Sub-tasks | E2: Story points | F2: Hours | G2: Done items | H2: Due
A3: E1 | B3: Documentation & planning | C3: =COUNTIFS('Jira Import'!$O:$O,A3,'Jira Import'!$B:$B,"Story") -> 4 | D3: =COUNTIFS('Jira Import'!$O:$O,A3,'Jira Import'!$B:$B,"Sub-task") -> 0 | E3: =SUMIFS('Jira Import'!$H:$H,'Jira Import'!$O:$O,A3) -> 10 | F3: =SUMIFS('Jira Import'!$I:$I,'Jira Import'!$O:$O,A3,'Jira Import'!$B:$B,"Story") -> 8.5 | G3: =COUNTIFS('Jira Import'!$O:$O,A3,'Jira Import'!$N:$N,"Done",'Jira Import'!$B:$B,"Story") -> 3 | H3: =IF(INDEX('Jira Import'!$L:$L,MATCH(A3,'Jira Import'!$A:$A,0))="","",INDEX('Jira Import'!$L:$L,MATCH(A3,'Jira Import'!$A:$A,0))) -> 46302
A4: E2 | B4: Environment & infrastructure setup | C4: =COUNTIFS('Jira Import'!$O:$O,A4,'Jira Import'!$B:$B,"Story") -> 10 | D4: =COUNTIFS('Jira Import'!$O:$O,A4,'Jira Import'!$B:$B,"Sub-task") -> 3 | E4: =SUMIFS('Jira Import'!$H:$H,'Jira Import'!$O:$O,A4) -> 21 | F4: =SUMIFS('Jira Import'!$I:$I,'Jira Import'!$O:$O,A4,'Jira Import'!$B:$B,"Story") -> 12.5 | G4: =COUNTIFS('Jira Import'!$O:$O,A4,'Jira Import'!$N:$N,"Done",'Jira Import'!$B:$B,"Story") -> 0 | H4: =IF(INDEX('Jira Import'!$L:$L,MATCH(A4,'Jira Import'!$A:$A,0))="","",INDEX('Jira Import'!$L:$L,MATCH(A4,'Jira Import'!$A:$A,0))) -> 46303
A5: E8 | B5: STRETCH: Edge, nginx and subdomains | C5: =COUNTIFS('Jira Import'!$O:$O,A5,'Jira Import'!$B:$B,"Story") -> 4 | D5: =COUNTIFS('Jira Import'!$O:$O,A5,'Jira Import'!$B:$B,"Sub-task") -> 0 | E5: =SUMIFS('Jira Import'!$H:$H,'Jira Import'!$O:$O,A5) -> 7 | F5: =SUMIFS('Jira Import'!$I:$I,'Jira Import'!$O:$O,A5,'Jira Import'!$B:$B,"Story") -> 3.5 | G5: =COUNTIFS('Jira Import'!$O:$O,A5,'Jira Import'!$N:$N,"Done",'Jira Import'!$B:$B,"Story") -> 0 | H5: =IF(INDEX('Jira Import'!$L:$L,MATCH(A5,'Jira Import'!$A:$A,0))="","",INDEX('Jira Import'!$L:$L,MATCH(A5,'Jira Import'!$A:$A,0)))
A6: E3 | B6: MI common layer | C6: =COUNTIFS('Jira Import'!$O:$O,A6,'Jira Import'!$B:$B,"Story") -> 7 | D6: =COUNTIFS('Jira Import'!$O:$O,A6,'Jira Import'!$B:$B,"Sub-task") -> 0 | E6: =SUMIFS('Jira Import'!$H:$H,'Jira Import'!$O:$O,A6) -> 14 | F6: =SUMIFS('Jira Import'!$I:$I,'Jira Import'!$O:$O,A6,'Jira Import'!$B:$B,"Story") -> 7 | G6: =COUNTIFS('Jira Import'!$O:$O,A6,'Jira Import'!$N:$N,"Done",'Jira Import'!$B:$B,"Story") -> 0 | H6: =IF(INDEX('Jira Import'!$L:$L,MATCH(A6,'Jira Import'!$A:$A,0))="","",INDEX('Jira Import'!$L:$L,MATCH(A6,'Jira Import'!$A:$A,0))) -> 46304
A7: E4 | B7: Balance API: GET /accounts/{accountNumber}/balance | C7: =COUNTIFS('Jira Import'!$O:$O,A7,'Jira Import'!$B:$B,"Story") -> 4 | D7: =COUNTIFS('Jira Import'!$O:$O,A7,'Jira Import'!$B:$B,"Sub-task") -> 0 | E7: =SUMIFS('Jira Import'!$H:$H,'Jira Import'!$O:$O,A7) -> 8 | F7: =SUMIFS('Jira Import'!$I:$I,'Jira Import'!$O:$O,A7,'Jira Import'!$B:$B,"Story") -> 4.5 | G7: =COUNTIFS('Jira Import'!$O:$O,A7,'Jira Import'!$N:$N,"Done",'Jira Import'!$B:$B,"Story") -> 0 | H7: =IF(INDEX('Jira Import'!$L:$L,MATCH(A7,'Jira Import'!$A:$A,0))="","",INDEX('Jira Import'!$L:$L,MATCH(A7,'Jira Import'!$A:$A,0))) -> 46304
A8: E5 | B8: Customer API: GET /customers/{customerId} | C8: =COUNTIFS('Jira Import'!$O:$O,A8,'Jira Import'!$B:$B,"Story") -> 4 | D8: =COUNTIFS('Jira Import'!$O:$O,A8,'Jira Import'!$B:$B,"Sub-task") -> 0 | E8: =SUMIFS('Jira Import'!$H:$H,'Jira Import'!$O:$O,A8) -> 7 | F8: =SUMIFS('Jira Import'!$I:$I,'Jira Import'!$O:$O,A8,'Jira Import'!$B:$B,"Story") -> 4 | G8: =COUNTIFS('Jira Import'!$O:$O,A8,'Jira Import'!$N:$N,"Done",'Jira Import'!$B:$B,"Story") -> 0 | H8: =IF(INDEX('Jira Import'!$L:$L,MATCH(A8,'Jira Import'!$A:$A,0))="","",INDEX('Jira Import'!$L:$L,MATCH(A8,'Jira Import'!$A:$A,0))) -> 46304
A9: E6 | B9: Loan Eligibility API: POST /loans/eligibility | C9: =COUNTIFS('Jira Import'!$O:$O,A9,'Jira Import'!$B:$B,"Story") -> 6 | D9: =COUNTIFS('Jira Import'!$O:$O,A9,'Jira Import'!$B:$B,"Sub-task") -> 0 | E9: =SUMIFS('Jira Import'!$H:$H,'Jira Import'!$O:$O,A9) -> 14 | F9: =SUMIFS('Jira Import'!$I:$I,'Jira Import'!$O:$O,A9,'Jira Import'!$B:$B,"Story") -> 7 | G9: =COUNTIFS('Jira Import'!$O:$O,A9,'Jira Import'!$N:$N,"Done",'Jira Import'!$B:$B,"Story") -> 0 | H9: =IF(INDEX('Jira Import'!$L:$L,MATCH(A9,'Jira Import'!$A:$A,0))="","",INDEX('Jira Import'!$L:$L,MATCH(A9,'Jira Import'!$A:$A,0))) -> 46305
A10: E7 | B10: API Manager exposure | C10: =COUNTIFS('Jira Import'!$O:$O,A10,'Jira Import'!$B:$B,"Story") -> 7 | D10: =COUNTIFS('Jira Import'!$O:$O,A10,'Jira Import'!$B:$B,"Sub-task") -> 0 | E10: =SUMIFS('Jira Import'!$H:$H,'Jira Import'!$O:$O,A10) -> 17 | F10: =SUMIFS('Jira Import'!$I:$I,'Jira Import'!$O:$O,A10,'Jira Import'!$B:$B,"Story") -> 9.5 | G10: =COUNTIFS('Jira Import'!$O:$O,A10,'Jira Import'!$N:$N,"Done",'Jira Import'!$B:$B,"Story") -> 0 | H10: =IF(INDEX('Jira Import'!$L:$L,MATCH(A10,'Jira Import'!$A:$A,0))="","",INDEX('Jira Import'!$L:$L,MATCH(A10,'Jira Import'!$A:$A,0))) -> 46306
A11: E10 | B11: CI/CD pipeline (Jenkins) | C11: =COUNTIFS('Jira Import'!$O:$O,A11,'Jira Import'!$B:$B,"Story") -> 9 | D11: =COUNTIFS('Jira Import'!$O:$O,A11,'Jira Import'!$B:$B,"Sub-task") -> 0 | E11: =SUMIFS('Jira Import'!$H:$H,'Jira Import'!$O:$O,A11) -> 22 | F11: =SUMIFS('Jira Import'!$I:$I,'Jira Import'!$O:$O,A11,'Jira Import'!$B:$B,"Story") -> 10.5 | G11: =COUNTIFS('Jira Import'!$O:$O,A11,'Jira Import'!$N:$N,"Done",'Jira Import'!$B:$B,"Story") -> 0 | H11: =IF(INDEX('Jira Import'!$L:$L,MATCH(A11,'Jira Import'!$A:$A,0))="","",INDEX('Jira Import'!$L:$L,MATCH(A11,'Jira Import'!$A:$A,0))) -> 46307
A12: E11 | B12: Testing & QA | C12: =COUNTIFS('Jira Import'!$O:$O,A12,'Jira Import'!$B:$B,"Story") -> 5 | D12: =COUNTIFS('Jira Import'!$O:$O,A12,'Jira Import'!$B:$B,"Sub-task") -> 0 | E12: =SUMIFS('Jira Import'!$H:$H,'Jira Import'!$O:$O,A12) -> 8 | F12: =SUMIFS('Jira Import'!$I:$I,'Jira Import'!$O:$O,A12,'Jira Import'!$B:$B,"Story") -> 3.5 | G12: =COUNTIFS('Jira Import'!$O:$O,A12,'Jira Import'!$N:$N,"Done",'Jira Import'!$B:$B,"Story") -> 0 | H12: =IF(INDEX('Jira Import'!$L:$L,MATCH(A12,'Jira Import'!$A:$A,0))="","",INDEX('Jira Import'!$L:$L,MATCH(A12,'Jira Import'!$A:$A,0))) -> 46307
A13: E9 | B13: STRETCH: Observability, ELK | C13: =COUNTIFS('Jira Import'!$O:$O,A13,'Jira Import'!$B:$B,"Story") -> 5 | D13: =COUNTIFS('Jira Import'!$O:$O,A13,'Jira Import'!$B:$B,"Sub-task") -> 0 | E13: =SUMIFS('Jira Import'!$H:$H,'Jira Import'!$O:$O,A13) -> 11 | F13: =SUMIFS('Jira Import'!$I:$I,'Jira Import'!$O:$O,A13,'Jira Import'!$B:$B,"Story") -> 5.5 | G13: =COUNTIFS('Jira Import'!$O:$O,A13,'Jira Import'!$N:$N,"Done",'Jira Import'!$B:$B,"Story") -> 0 | H13: =IF(INDEX('Jira Import'!$L:$L,MATCH(A13,'Jira Import'!$A:$A,0))="","",INDEX('Jira Import'!$L:$L,MATCH(A13,'Jira Import'!$A:$A,0)))
A14: E12 | B14: Submission | C14: =COUNTIFS('Jira Import'!$O:$O,A14,'Jira Import'!$B:$B,"Story") -> 6 | D14: =COUNTIFS('Jira Import'!$O:$O,A14,'Jira Import'!$B:$B,"Sub-task") -> 0 | E14: =SUMIFS('Jira Import'!$H:$H,'Jira Import'!$O:$O,A14) -> 10 | F14: =SUMIFS('Jira Import'!$I:$I,'Jira Import'!$O:$O,A14,'Jira Import'!$B:$B,"Story") -> 7 | G14: =COUNTIFS('Jira Import'!$O:$O,A14,'Jira Import'!$N:$N,"Done",'Jira Import'!$B:$B,"Story") -> 0 | H14: =IF(INDEX('Jira Import'!$L:$L,MATCH(A14,'Jira Import'!$A:$A,0))="","",INDEX('Jira Import'!$L:$L,MATCH(A14,'Jira Import'!$A:$A,0))) -> 46307
A15: E13 | B15: Bonus (optional) | C15: =COUNTIFS('Jira Import'!$O:$O,A15,'Jira Import'!$B:$B,"Story") -> 2 | D15: =COUNTIFS('Jira Import'!$O:$O,A15,'Jira Import'!$B:$B,"Sub-task") -> 0 | E15: =SUMIFS('Jira Import'!$H:$H,'Jira Import'!$O:$O,A15) -> 13 | F15: =SUMIFS('Jira Import'!$I:$I,'Jira Import'!$O:$O,A15,'Jira Import'!$B:$B,"Story") -> 7 | G15: =COUNTIFS('Jira Import'!$O:$O,A15,'Jira Import'!$N:$N,"Done",'Jira Import'!$B:$B,"Story") -> 0 | H15: =IF(INDEX('Jira Import'!$L:$L,MATCH(A15,'Jira Import'!$A:$A,0))="","",INDEX('Jira Import'!$L:$L,MATCH(A15,'Jira Import'!$A:$A,0)))
A16: Total | C16: =SUM(C3:C15) -> 73 | D16: =SUM(D3:D15) -> 3 | E16: =SUM(E3:E15) -> 162 | F16: =SUM(F3:F15) -> 90 | G16: =SUM(G3:G15) -> 3
A17: Hours count stories only; sub-task hours are a breakdown of their parent story's estimate.
A19: Daily load (story hours by due date)
A20: Day | B20: Date | C20: Stories due | D20: Hours | E20: Capacity (h) | F20: Over / (under)
A21: Wed | B21: 46302 | C21: =COUNTIFS('Jira Import'!$L:$L,B21,'Jira Import'!$B:$B,"Story") -> 6 | D21: =SUMIFS('Jira Import'!$I:$I,'Jira Import'!$L:$L,B21,'Jira Import'!$B:$B,"Story") -> 11 | E21: 11 | F21: =D21-E21 -> 0
A22: Thu | B22: 46303 | C22: =COUNTIFS('Jira Import'!$L:$L,B22,'Jira Import'!$B:$B,"Story") -> 11 | D22: =SUMIFS('Jira Import'!$I:$I,'Jira Import'!$L:$L,B22,'Jira Import'!$B:$B,"Story") -> 13 | E22: 13 | F22: =D22-E22 -> 0
A23: Fri | B23: 46304 | C23: =COUNTIFS('Jira Import'!$L:$L,B23,'Jira Import'!$B:$B,"Story") -> 12 | D23: =SUMIFS('Jira Import'!$I:$I,'Jira Import'!$L:$L,B23,'Jira Import'!$B:$B,"Story") -> 12.5 | E23: 13 | F23: =D23-E23 -> -0.5
A24: Sat | B24: 46305 | C24: =COUNTIFS('Jira Import'!$L:$L,B24,'Jira Import'!$B:$B,"Story") -> 9 | D24: =SUMIFS('Jira Import'!$I:$I,'Jira Import'!$L:$L,B24,'Jira Import'!$B:$B,"Story") -> 12.5 | E24: 13 | F24: =D24-E24 -> -0.5
A25: Sun | B25: 46306 | C25: =COUNTIFS('Jira Import'!$L:$L,B25,'Jira Import'!$B:$B,"Story") -> 12 | D25: =SUMIFS('Jira Import'!$I:$I,'Jira Import'!$L:$L,B25,'Jira Import'!$B:$B,"Story") -> 13 | E25: 13 | F25: =D25-E25 -> 0
A26: Mon | B26: 46307 | C26: =COUNTIFS('Jira Import'!$L:$L,B26,'Jira Import'!$B:$B,"Story") -> 12 | D26: =SUMIFS('Jira Import'!$I:$I,'Jira Import'!$L:$L,B26,'Jira Import'!$B:$B,"Story") -> 12 | E26: 13 | F26: =D26-E26 -> -1
A27: Capacity (yellow): long days of 13 h Thu-Mon; Wed = 8 h docs already done + 3 h this evening. Edit to your real availability.

Sheet Jira Import
A1: Issue ID | B1: Issue Type | C1: Summary | D1: Description | E1: Parent ID | F1: Priority | G1: Labels | H1: Story Points | I1: Original Estimate (h) | J1: Original Estimate (s) | K1: Start Date | L1: Due Date | M1: Component | N1: Status | O1: Epic (rollup)
A2: E1 | B2: Epic | C2: Documentation & planning | D2: BRD, Solution Design Document and Jira plan for the Jamii Savings integration platform. | F2: Highest | G2: docs | J2: =IF(I2="","",I2*3600) | K2: 46302 | L2: 46302 | M2: Docs | N2: To Do | O2: E1
A3: S1.1 | B3: Story | C3: Business Requirements Document v1.1 | D3: BRD covering scope, FR/NFR, error matrix, risks, acceptance and traceability. AC: final draft approved. | E3: E1 | F3: High | G3: docs | H3: 3 | I3: 3 | J3: =IF(I3="","",I3*3600) -> 10800 | K3: 46302 | L3: 46302 | M3: Docs | N3: Done | O3: E1
A4: S1.2 | B4: Story | C4: Solution Design Document v1.1 with diagrams | D4: Architecture, loan sequence, pipeline and edge topology diagrams; ADR log. AC: final draft approved. | E4: E1 | F4: High | G4: docs | H4: 5 | I4: 4 | J4: =IF(I4="","",I4*3600) -> 14400 | K4: 46302 | L4: 46302 | M4: Docs | N4: Done | O4: E1
A5: S1.3 | B5: Story | C5: Jira project plan | D5: This workbook: epics, stories, sub-tasks, estimates and dates. AC: imported into Jira. | E5: E1 | F5: High | G5: docs | H5: 1 | I5: 1 | J5: =IF(I5="","",I5*3600) -> 3600 | K5: 46302 | L5: 46302 | M5: Docs | N5: Done | O5: E1
A6: S1.4 | B6: Story | C6: Create Jira project and import plan | D6: Create project, import CSV, check hierarchy and dates. AC: board shows all epics and stories. | E6: E1 | F6: High | G6: docs | H6: 1 | I6: 0.5 | J6: =IF(I6="","",I6*3600) -> 1800 | K6: 46302 | L6: 46302 | M6: Docs | N6: To Do | O6: E1
A7: E2 | B7: Epic | C7: Environment & infrastructure setup | D7: Workstation, repository, WSO2 distributions, Docker images and docker-compose stack. | F7: Highest | G7: infrastructure | J7: =IF(I7="","",I7*3600) | K7: 46302 | L7: 46303 | M7: Infrastructure | N7: To Do | O7: E2
A8: S2.1 | B8: Story | C8: Workstation prerequisites | D8: Install and verify Docker (10-12 GB RAM allocated), JDK 21, Maven 3.9, apictl, curl, jq, Git and the MI VS Code extension. AC: versions recorded in README. | E8: E2 | F8: Highest | G8: infrastructure | H8: 2 | I8: 1.5 | J8: =IF(I8="","",I8*3600) -> 5400 | K8: 46302 | L8: 46302 | M8: Infrastructure | N8: To Do | O8: E2
A9: T2.1.1 | B9: Sub-task | C9: Confirm supported JDK for chosen MI/APIM release | D9: Check release notes; set base image JDK accordingly. | E9: S2.1 | F9: High | G9: infrastructure | I9: 0.5 | J9: =IF(I9="","",I9*3600) -> 1800 | K9: 46302 | L9: 46302 | M9: Infrastructure | N9: To Do | O9: E2
A10: S2.2 | B10: Story | C10: Git repository scaffold | D10: Create repo per SDD section 10; .gitignore (dist zips, certs, .env), .env.example, README skeleton; push to GitHub. AC: clean clone shows full structure. | E10: E2 | F10: Highest | G10: infrastructure | H10: 1 | I10: 1 | J10: =IF(I10="","",I10*3600) -> 3600 | K10: 46302 | L10: 46302 | M10: Infrastructure | N10: To Do | O10: E2
A11: S2.3 | B11: Story | C11: Download WSO2 APIM and MI distributions | D11: Download latest matching 4.4.x zips into dist/; record SHA-256 in dist/checksums.txt. AC: checksums verified. | E11: E2 | F11: Highest | G11: infrastructure | H11: 1 | I11: 0.5 | J11: =IF(I11="","",I11*3600) -> 1800 | K11: 46303 | L11: 46303 | M11: Infrastructure | N11: To Do | O11: E2
A12: S2.4 | B12: Story | C12: Build jamii/mi image | D12: Multi-stage Dockerfile from eclipse-temurin + MI zip; non-root user; H2 driver in lib; log4j2 config; additional_contexts for dist. AC: container starts, management API answers on 9164. | E12: E2 | F12: Highest | G12: infrastructure | H12: 3 | I12: 2 | J12: =IF(I12="","",I12*3600) -> 7200 | K12: 46303 | L12: 46303 | M12: Infrastructure | N12: To Do | O12: E2
A13: S2.5 | B13: Story | C13: Build jamii/apim image | D13: Multi-stage Dockerfile from APIM zip; deployment.toml with public hostnames, proxy port 443, ELK analytics, admin creds from env; replace default keystores. AC: Publisher and Dev Portal log in on localhost:9443. | E13: E2 | F13: Highest | G13: infrastructure | H13: 5 | I13: 3 | J13: =IF(I13="","",I13*3600) -> 10800 | K13: 46303 | L13: 46303 | M13: Infrastructure | N13: To Do | O13: E2
A14: T2.5.1 | B14: Sub-task | C14: Configure deployment.toml for localhost | D14: Server hostname localhost; public hostnames and proxy port 443 are added with the nginx stretch (E8). | E14: S2.5 | F14: High | G14: infrastructure | I14: 1 | J14: =IF(I14="","",I14*3600) -> 3600 | K14: 46303 | L14: 46303 | M14: Infrastructure | N14: To Do | O14: E2
A15: T2.5.2 | B15: Sub-task | C15: Replace default keystores and admin credentials | D15: Project self-signed keystore; admin password from env. | E15: S2.5 | F15: High | G15: infrastructure | I15: 1 | J15: =IF(I15="","",I15*3600) -> 3600 | K15: 46303 | L15: 46303 | M15: Infrastructure | N15: To Do | O15: E2
A16: S2.6 | B16: Story | C16: DB schema and seed scripts | D16: db/schema.sql (accounts, CHECK on status) and db/seed.sql (one account per status plus a zero balance). AC: scripts run cleanly on H2. | E16: E2 | F16: Highest | G16: infrastructure | H16: 1 | I16: 0.5 | J16: =IF(I16="","",I16*3600) -> 1800 | K16: 46303 | L16: 46303 | M16: Infrastructure | N16: To Do | O16: E2
A17: S2.7 | B17: Story | C17: Build jamii/h2 image | D17: Temurin + H2 jar; RunScript schema and seed, then TCP server on 9092; healthcheck. AC: MI datasource connects. | E17: E2 | F17: Highest | G17: infrastructure | H17: 2 | I17: 1 | J17: =IF(I17="","",I17*3600) -> 3600 | K17: 46303 | L17: 46303 | M17: Infrastructure | N17: To Do | O17: E2
A18: S2.8 | B18: Story | C18: Build jamii/wiremock image | D18: Stubs mirroring the Beeceptor customer rules and DNE Divide, plus fault scenarios (delay, reset, SOAP fault). AC: stubs answer on 8089 and match beeceptor-rules.json. | E18: E2 | F18: High | G18: infrastructure | H18: 2 | I18: 1 | J18: =IF(I18="","",I18*3600) -> 3600 | K18: 46303 | L18: 46303 | M18: Infrastructure | N18: To Do | O18: E2
A19: S2.9 | B19: Story | C19: docker-compose.yml with profiles | D19: Services, jamii-net network, healthchecks, depends_on; profiles core, observability, ci. AC: compose --profile core up is healthy. | E19: E2 | F19: Highest | G19: infrastructure | H19: 3 | I19: 1.5 | J19: =IF(I19="","",I19*3600) -> 5400 | K19: 46303 | L19: 46303 | M19: Infrastructure | N19: To Do | O19: E2
A20: S2.10 | B20: Story | C20: Local image registry and tagging | D20: registry:2 service; images tagged with ${TAG} (build number). AC: push and pull work. | E20: E2 | F20: High | G20: infrastructure | H20: 1 | I20: 0.5 | J20: =IF(I20="","",I20*3600) -> 1800 | K20: 46303 | L20: 46303 | M20: Infrastructure | N20: To Do | O20: E2
A21: E8 | B21: Epic | C21: STRETCH: Edge, nginx and subdomains | D21: Stretch goal: start only after the pipeline is green. nginx as the single public entry with TLS and one subdomain per service under jamii.daqiqtech.co.ke. | F21: Low | G21: edge | J21: =IF(I21="","",I21*3600) | M21: Edge | N21: To Do | O21: E8
A22: S8.1 | B22: Story | C22: Build jamii/nginx image with server blocks | D22: Server blocks for api., portal., apim., mi., kibana., jenkins. (dev: *.dev.jamii.daqiqtech.co.ke). AC: each host routes to its service. | E22: E8 | F22: Low | G22: edge | H22: 3 | I22: 1.5 | J22: =IF(I22="","",I22*3600) -> 5400 | M22: Edge | N22: To Do | O22: E8
A23: S8.2 | B23: Story | C23: Wildcard TLS certificate and hosts entries | D23: mkcert wildcard for *.dev.jamii.daqiqtech.co.ke; /etc/hosts entries to 127.0.0.1. AC: all six hosts load over HTTPS without warnings. | E23: E8 | F23: Low | G23: edge | H23: 1 | I23: 0.5 | J23: =IF(I23="","",I23*3600) -> 1800 | M23: Edge | N23: To Do | O23: E8
A24: S8.3 | B24: Story | C24: Access controls on admin hosts | D24: IP allowlist on apim., mi., kibana., jenkins.; client_max_body_size 50m on apim.; proxy_ssl_verify off for internal HTTPS. AC: non-allowlisted IP gets 403. | E24: E8 | F24: Low | G24: edge | H24: 2 | I24: 1 | J24: =IF(I24="","",I24*3600) -> 3600 | M24: Edge | N24: To Do | O24: E8
A25: S8.4 | B25: Story | C25: Verify edge security | D25: Confirm MI 8290, Elasticsearch, H2 and registry are unreachable from outside the Docker network. AC: evidence in README. | E25: E8 | F25: Low | G25: edge | H25: 1 | I25: 0.5 | J25: =IF(I25="","",I25*3600) -> 1800 | M25: Edge | N25: To Do | O25: E8
A26: E3 | B26: Epic | C26: MI common layer | D26: Shared sequences, templates and class mediator used by all three APIs. | F26: Highest | G26: mi-common | J26: =IF(I26="","",I26*3600) | K26: 46303 | L26: 46304 | M26: MI Common | N26: To Do | O26: E3
A27: S3.1 | B27: Story | C27: MI multi-module Maven project | D27: Modules: common, balance-api, customer-api, loan-api, composite. AC: mvn clean install builds a CAR. | E27: E3 | F27: Highest | G27: mi-common | H27: 2 | I27: 1 | J27: =IF(I27="","",I27*3600) -> 3600 | K27: 46303 | L27: 46303 | M27: MI Common | N27: To Do | O27: E3
A28: S3.2 | B28: Story | C28: Common_InSeq: correlation ID | D28: Read or generate X-Correlation-ID (UUID v4); store as property; record start time. AC: ID returned on every response. | E28: E3 | F28: Highest | G28: mi-common | H28: 1 | I28: 0.5 | J28: =IF(I28="","",I28*3600) -> 1800 | K28: 46303 | L28: 46303 | M28: MI Common | N28: To Do | O28: E3
A29: S3.3 | B29: Story | C29: MaskingMediator class mediator | D29: Mask account numbers (last 4) and PII fields; drop financial amounts. AC: JUnit tests pass. | E29: E3 | F29: Highest | G29: mi-common | H29: 3 | I29: 1.5 | J29: =IF(I29="","",I29*3600) -> 5400 | K29: 46303 | L29: 46303 | M29: MI Common | N29: To Do | O29: E3
A30: S3.4 | B30: Story | C30: Common_MaskedLog template | D30: Logs REQUEST_IN, BACKEND_CALL, RESPONSE_OUT as key=value with masked fields. AC: three lines per request, no raw PII. | E30: E3 | F30: Highest | G30: mi-common | H30: 2 | I30: 1 | J30: =IF(I30="","",I30*3600) -> 3600 | K30: 46304 | L30: 46304 | M30: MI Common | N30: To Do | O30: E3
A31: S3.5 | B31: Story | C31: Common_ErrorResponse template | D31: Builds standard error JSON (code, message, httpStatus, details, requestId, timestamp). AC: validates against error schema. | E31: E3 | F31: Highest | G31: mi-common | H31: 2 | I31: 1 | J31: =IF(I31="","",I31*3600) -> 3600 | K31: 46304 | L31: 46304 | M31: MI Common | N31: To Do | O31: E3
A32: S3.6 | B32: Story | C32: Common_FaultSeq | D32: Classify timeout (504), connection (503), SQL (503 DB_UNAVAILABLE), malformed JSON (400), other (500). AC: no stack trace ever returned. | E32: E3 | F32: Highest | G32: mi-common | H32: 3 | I32: 1.5 | J32: =IF(I32="","",I32*3600) -> 5400 | K32: 46304 | L32: 46304 | M32: MI Common | N32: To Do | O32: E3
A33: S3.7 | B33: Story | C33: Common_HeaderHygiene | D33: Strip X-Internal-*, Server, X-Powered-By, Set-Cookie inbound and outbound. AC: headers absent in responses. | E33: E3 | F33: High | G33: mi-common | H33: 1 | I33: 0.5 | J33: =IF(I33="","",I33*3600) -> 1800 | K33: 46304 | L33: 46304 | M33: MI Common | N33: To Do | O33: E3
A34: E4 | B34: Epic | C34: Balance API: GET /accounts/{accountNumber}/balance | D34: DB-backed API using MI Data Services over H2. | F34: Highest | G34: balance-api | J34: =IF(I34="","",I34*3600) | K34: 46304 | L34: 46304 | M34: Balance API | N34: To Do | O34: E4
A35: S4.1 | B35: Story | C35: Datasource JamiiAccountsDS | D35: JDBC pool to jdbc:h2:tcp://h2:9092/jamii; credentials from env. AC: pool connects at startup. | E35: E4 | F35: Highest | G35: balance-api | H35: 1 | I35: 0.5 | J35: =IF(I35="","",I35*3600) -> 1800 | K35: 46304 | L35: 46304 | M35: Balance API | N35: To Do | O35: E4
A36: S4.2 | B36: Story | C36: AccountsDataService parameterised query | D36: getAccountByNumber with a bound parameter. AC: no string-built SQL. | E36: E4 | F36: Highest | G36: balance-api | H36: 2 | I36: 1 | J36: =IF(I36="","",I36*3600) -> 3600 | K36: 46304 | L36: 46304 | M36: Balance API | N36: To Do | O36: E4
A37: S4.3 | B37: Story | C37: BalanceAPI resource and envelope | D37: Regex validation (400), envelope via PayloadFactory, 404 ACCOUNT_NOT_FOUND, 503 DB_UNAVAILABLE. AC: matches BRD 8.2 envelope. | E37: E4 | F37: Highest | G37: balance-api | H37: 3 | I37: 2 | J37: =IF(I37="","",I37*3600) -> 7200 | K37: 46304 | L37: 46304 | M37: Balance API | N37: To Do | O37: E4
A38: S4.4 | B38: Story | C38: Balance API unit tests | D38: MI unit test suite for 200, 400, 404 against the H2 container. AC: tests run in mvn build. | E38: E4 | F38: High | G38: balance-api | H38: 2 | I38: 1 | J38: =IF(I38="","",I38*3600) -> 3600 | K38: 46304 | L38: 46304 | M38: Balance API | N38: To Do | O38: E4
A39: E5 | B39: Epic | C39: Customer API: GET /customers/{customerId} | D39: Managed proxy in front of a Beeceptor mock endpoint with gateway value; WireMock mirror for CI. | F39: Highest | G39: customer-api | J39: =IF(I39="","",I39*3600) | K39: 46304 | L39: 46304 | M39: Customer API | N39: To Do | O39: E5
A40: S5.1 | B40: Story | C40: CustomerBackendEP | D40: HTTP endpoint with 5 s timeout and configurable base URL (Beeceptor for demo, WireMock for CI). AC: switch backend by env var only. | E40: E5 | F40: Highest | G40: customer-api | H40: 1 | I40: 0.5 | J40: =IF(I40="","",I40*3600) -> 1800 | K40: 46304 | L40: 46304 | M40: Customer API | N40: To Do | O40: E5
...

Sheet How to import
A1: How to import into Jira
A2: 1. Jira imports CSV, not .xlsx. Use the companion file jamii-jira-import.csv (same rows, computed values).
A3: 2. Jira: Settings (cog) > System > External System Import > CSV (company-managed), or Project > Import work items (team-managed).
A4: 3. Date format setting: yyyy-MM-dd. File encoding: UTF-8.
A5: 4. Field mapping: Issue ID > Issue Id; Parent ID > Parent Id; Issue Type, Summary, Description, Priority, Labels, Component, Status, Due Date, Start Date as named; Story Points > Story point estimate; Original Estimate (s) > Original Estimate.
A6: 5. Do not map 'Original Estimate (h)' or 'Epic (rollup)'; they exist for this workbook's Summary sheet.
A7: 6. Status 'Done' only imports if your workflow has a Done status; otherwise map it to the nearest status.
A8: 7. If Components do not exist in the project yet, let the importer create them or create them first.
A10: Editing
A11: Edit rows on 'Jira Import'. The Summary sheet recalculates. Yellow cells on Summary are the only manual inputs.
